Failure # 1 (occurred at 2022-02-09_01-36-19)
Traceback (most recent call last):
  File "/DATA/chowdari1/.local/lib/python3.7/site-packages/ray/tune/trial_runner.py", line 924, in _process_trial
    results = self.trial_executor.fetch_result(trial)
  File "/DATA/chowdari1/.local/lib/python3.7/site-packages/ray/tune/ray_trial_executor.py", line 787, in fetch_result
    result = ray.get(trial_future[0], timeout=DEFAULT_GET_TIMEOUT)
  File "/DATA/chowdari1/.local/lib/python3.7/site-packages/ray/_private/client_mode_hook.py", line 105, in wrapper
    return func(*args, **kwargs)
  File "/DATA/chowdari1/.local/lib/python3.7/site-packages/ray/worker.py", line 1713, in get
    raise value.as_instanceof_cause()
ray.exceptions.RayTaskError(TuneError): [36mray::ImplicitFunc.train_buffered()[39m (pid=19678, ip=172.25.0.208, repr=<ray.tune.function_runner.ImplicitFunc object at 0x7efe0c37ce48>)
  File "/DATA/chowdari1/.local/lib/python3.7/site-packages/ray/tune/trainable.py", line 255, in train_buffered
    result = self.train()
  File "/DATA/chowdari1/.local/lib/python3.7/site-packages/ray/tune/trainable.py", line 314, in train
    result = self.step()
  File "/DATA/chowdari1/.local/lib/python3.7/site-packages/ray/tune/function_runner.py", line 381, in step
    self._report_thread_runner_error(block=True)
  File "/DATA/chowdari1/.local/lib/python3.7/site-packages/ray/tune/function_runner.py", line 532, in _report_thread_runner_error
    ("Trial raised an exception. Traceback:\n{}".format(err_tb_str)
ray.tune.error.TuneError: Trial raised an exception. Traceback:
[36mray::ImplicitFunc.train_buffered()[39m (pid=19678, ip=172.25.0.208, repr=<ray.tune.function_runner.ImplicitFunc object at 0x7efe0c37ce48>)
  File "/DATA/chowdari1/.local/lib/python3.7/site-packages/ray/tune/function_runner.py", line 262, in run
    self._entrypoint()
  File "/DATA/chowdari1/.local/lib/python3.7/site-packages/ray/tune/function_runner.py", line 331, in entrypoint
    self._status_reporter.get_checkpoint())
  File "/DATA/chowdari1/.local/lib/python3.7/site-packages/ray/tune/function_runner.py", line 597, in _trainable_func
    output = fn()
  File "/tmp/ipykernel_3885/2932301558.py", line 4, in train
  File "/tmp/ipykernel_3885/1736512985.py", line 6, in __init__
  File "/tmp/ipykernel_3885/4266227846.py", line 18, in __init__
RuntimeError: CUDA error: out of memory
CUDA kernel errors might be asynchronously reported at some other API call,so the stacktrace below might be incorrect.
For debugging consider passing CUDA_LAUNCH_BLOCKING=1.

