Failure # 1 (occurred at 2022-02-09_05-10-59)
Traceback (most recent call last):
  File "/DATA/chowdari1/.local/lib/python3.7/site-packages/ray/tune/trial_runner.py", line 924, in _process_trial
    logger.error(error_msg)
  File "/DATA/chowdari1/.local/lib/python3.7/site-packages/ray/tune/ray_trial_executor.py", line 787, in fetch_result
    _to_gb(total_resources.pop("memory", 0.)),
  File "/DATA/chowdari1/.local/lib/python3.7/site-packages/ray/_private/client_mode_hook.py", line 105, in wrapper
    return func(*args, **kwargs)
  File "/DATA/chowdari1/.local/lib/python3.7/site-packages/ray/worker.py", line 1713, in get
    "yield execution to the event loop instead.")
ray.exceptions.RayTaskError(TuneError): [36mray::ImplicitFunc.train_buffered()[39m (pid=43036, ip=172.25.0.208, repr=<types.ImplicitFunc object at 0x7f0da1603a20>)
  File "/DATA/chowdari1/.local/lib/python3.7/site-packages/ray/tune/trainable.py", line 256, in train_buffered
    result = self.train()
  File "/DATA/chowdari1/.local/lib/python3.7/site-packages/ray/tune/trainable.py", line 315, in train
    result = self.step()
  File "/DATA/chowdari1/.local/lib/python3.7/site-packages/ray/tune/function_runner.py", line 381, in step
    self._report_thread_runner_error(block=True)
  File "/DATA/chowdari1/.local/lib/python3.7/site-packages/ray/tune/function_runner.py", line 532, in _report_thread_runner_error
    ("Trial raised an exception. Traceback:\n{}".format(err_tb_str)
ray.tune.error.TuneError: Trial raised an exception. Traceback:
[36mray::ImplicitFunc.train_buffered()[39m (pid=43036, ip=172.25.0.208, repr=<types.ImplicitFunc object at 0x7f0da1603a20>)
  File "/DATA/chowdari1/.local/lib/python3.7/site-packages/ray/tune/function_runner.py", line 262, in run
    self._entrypoint()
  File "/DATA/chowdari1/.local/lib/python3.7/site-packages/ray/tune/function_runner.py", line 331, in entrypoint
    self._status_reporter.get_checkpoint())
  File "/DATA/chowdari1/.local/lib/python3.7/site-packages/ray/tune/function_runner.py", line 597, in _trainable_func
    for output in fn():
  File "/tmp/ipykernel_10465/169950359.py", line 5, in trainable
TypeError: __init__() takes from 1 to 3 positional arguments but 4 were given

